Traceback (most recent call last):
  File "/opt/hostedtoolcache/Python/3.9.21/x64/lib/python3.9/site-packages/jupyter_cache/executors/utils.py", line 58, in single_nb_execution
    executenb(
  File "/opt/hostedtoolcache/Python/3.9.21/x64/lib/python3.9/site-packages/nbclient/client.py", line 1319, in execute
    return NotebookClient(nb=nb, resources=resources, km=km, **kwargs).execute()
  File "/opt/hostedtoolcache/Python/3.9.21/x64/lib/python3.9/site-packages/jupyter_core/utils/__init__.py", line 165, in wrapped
    return loop.run_until_complete(inner)
  File "/opt/hostedtoolcache/Python/3.9.21/x64/lib/python3.9/asyncio/base_events.py", line 647, in run_until_complete
    return future.result()
  File "/opt/hostedtoolcache/Python/3.9.21/x64/lib/python3.9/site-packages/nbclient/client.py", line 709, in async_execute
    await self.async_execute_cell(
  File "/opt/hostedtoolcache/Python/3.9.21/x64/lib/python3.9/site-packages/nbclient/client.py", line 1062, in async_execute_cell
    await self._check_raise_for_error(cell, cell_index, exec_reply)
  File "/opt/hostedtoolcache/Python/3.9.21/x64/lib/python3.9/site-packages/nbclient/client.py", line 918, in _check_raise_for_error
    raise CellExecutionError.from_cell_and_msg(cell, exec_reply_content)
nbclient.exceptions.CellExecutionError: An error occurred while executing the following cell:
------------------
import numpy as np
import pandas as pd

time = np.arange(0, 10)
XrayPulses = np.array([4.67, 6.07, 4.19, 4.63, 6.77, 3.69, 5.20, 4.87, 5.85, 4.73])
RadioPulsesSat = np.array([1.73, 2.24, 1.60, 1.64, 2.43, 1.26, 1.91, 1.58, 2.22, 1.67])
RadioPulsesLab = np.array([1.94, 1.16, 2.01, 2.19, 1.55, 2.05, 2.20, 2.35, 2.12, 2.19])

XrayPulses *= 10**6
RadioPulsesSat *= 10**5
RadioPulsesLab *= 10**5

data = {
    "time": time,
    "x-ray pulses": XrayPulses,
    "radio pulses satellite": RadioPulsesSat,
    "radio pulses laboratory": RadioPulsesLab,
}

df = pd.DataFrame(data)
df
------------------


[0;31m---------------------------------------------------------------------------[0m
[0;31mModuleNotFoundError[0m                       Traceback (most recent call last)
Cell [0;32mIn[1], line 2[0m
[1;32m      1[0m [38;5;28;01mimport[39;00m[38;5;250m [39m[38;5;21;01mnumpy[39;00m[38;5;250m [39m[38;5;28;01mas[39;00m[38;5;250m [39m[38;5;21;01mnp[39;00m
[0;32m----> 2[0m [38;5;28;01mimport[39;00m[38;5;250m [39m[38;5;21;01mpandas[39;00m[38;5;250m [39m[38;5;28;01mas[39;00m[38;5;250m [39m[38;5;21;01mpd[39;00m
[1;32m      4[0m time [38;5;241m=[39m np[38;5;241m.[39marange([38;5;241m0[39m, [38;5;241m10[39m)
[1;32m      5[0m XrayPulses [38;5;241m=[39m np[38;5;241m.[39marray([[38;5;241m4.67[39m, [38;5;241m6.07[39m, [38;5;241m4.19[39m, [38;5;241m4.63[39m, [38;5;241m6.77[39m, [38;5;241m3.69[39m, [38;5;241m5.20[39m, [38;5;241m4.87[39m, [38;5;241m5.85[39m, [38;5;241m4.73[39m])

[0;31mModuleNotFoundError[0m: No module named 'pandas'

